{
    DataVersion: 3955,
    size: [3, 7, 3],
    data: [
        {pos: [0, 0, 0], state: "actualgenerators:machine_casing{formed:true}"},
        {pos: [0, 0, 1], state: "actualgenerators:machine_casing{formed:true}"},
        {pos: [0, 0, 2], state: "actualgenerators:machine_casing{formed:true}"},
        {pos: [1, 0, 0], state: "actualgenerators:machine_casing{formed:true}"},
        {pos: [1, 0, 0], state: "actualgenerators:annihilation_furnace{facing:north,formed:true}"},
        {pos: [1, 0, 1], state: "actualgenerators:machine_casing{formed:true}"},
        {pos: [1, 0, 2], state: "actualgenerators:machine_casing{formed:true}"},
        {pos: [2, 0, 0], state: "actualgenerators:machine_casing{formed:true}"},
        {pos: [2, 0, 1], state: "actualgenerators:machine_casing{formed:true}"},
        {pos: [2, 0, 2], state: "actualgenerators:machine_casing{formed:true}"},
        {pos: [0, 1, 0], state: "actualgenerators:machine_casing{formed:true}"},
        {pos: [0, 1, 1], state: "actualgenerators:machine_casing{formed:true}"},
        {pos: [0, 1, 2], state: "actualgenerators:machine_casing{formed:true}"},
        {pos: [1, 1, 0], state: "actualgenerators:machine_casing{formed:true}"},
        {pos: [1, 1, 1], state: "actualgenerators:corium{level:0}"},
        {pos: [1, 1, 2], state: "actualgenerators:machine_casing{formed:true}"},
        {pos: [2, 1, 0], state: "actualgenerators:machine_casing{formed:true}"},
        {pos: [2, 1, 1], state: "actualgenerators:machine_casing{formed:true}"},
        {pos: [2, 1, 2], state: "actualgenerators:machine_casing{formed:true}"},
        {pos: [0, 2, 0], state: "actualgenerators:machine_casing{formed:true}"},
        {pos: [0, 2, 1], state: "actualgenerators:machine_casing{formed:true}"},
        {pos: [0, 2, 2], state: "actualgenerators:machine_casing{formed:true}"},
        {pos: [1, 2, 0], state: "actualgenerators:machine_casing{formed:true}"},
        {pos: [1, 2, 2], state: "actualgenerators:machine_casing{formed:true}"},
        {pos: [2, 2, 0], state: "actualgenerators:machine_casing{formed:true}"},
        {pos: [2, 2, 1], state: "actualgenerators:machine_casing{formed:true}"},
        {pos: [2, 2, 2], state: "actualgenerators:machine_casing{formed:true}"},
        {pos: [0, 3, 0], state: "actualgenerators:machine_casing{formed:true}"},
        {pos: [0, 3, 1], state: "actualgenerators:machine_casing{formed:true}"},
        {pos: [0, 3, 1], state: "actualgenerators:item_hatch{facing:north,formed:true}"},
        {pos: [0, 3, 2], state: "actualgenerators:machine_casing{formed:true}"},
        {pos: [1, 3, 0], state: "actualgenerators:machine_casing{formed:true}"},
        {pos: [1, 3, 2], state: "actualgenerators:machine_casing{formed:true}"},
        {pos: [1, 3, 2], state: "actualgenerators:redstone_hatch{facing:north,formed:true}"},
        {pos: [2, 3, 0], state: "actualgenerators:machine_casing{formed:true}"},
        {pos: [2, 3, 1], state: "actualgenerators:machine_casing{formed:true}"},
        {pos: [2, 3, 1], state: "actualgenerators:energy_hatch{facing:north,formed:true}"},
        {pos: [2, 3, 2], state: "actualgenerators:machine_casing{formed:true}"},
        {pos: [0, 4, 0], state: "actualgenerators:machine_casing{formed:true}"},
        {pos: [0, 4, 1], state: "actualgenerators:machine_casing{formed:true}"},
        {pos: [0, 4, 2], state: "actualgenerators:machine_casing{formed:true}"},
        {pos: [1, 4, 0], state: "actualgenerators:machine_casing{formed:true}"},
        {pos: [1, 4, 2], state: "actualgenerators:machine_casing{formed:true}"},
        {pos: [2, 4, 0], state: "actualgenerators:machine_casing{formed:true}"},
        {pos: [2, 4, 1], state: "actualgenerators:machine_casing{formed:true}"},
        {pos: [2, 4, 2], state: "actualgenerators:machine_casing{formed:true}"},
        {pos: [0, 5, 0], state: "actualgenerators:machine_casing{formed:true}"},
        {pos: [0, 5, 1], state: "actualgenerators:machine_casing{formed:true}"},
        {pos: [0, 5, 2], state: "actualgenerators:machine_casing{formed:true}"},
        {pos: [1, 5, 0], state: "actualgenerators:machine_casing{formed:true}"},
        {pos: [1, 5, 2], state: "actualgenerators:machine_casing{formed:true}"},
        {pos: [2, 5, 0], state: "actualgenerators:machine_casing{formed:true}"},
        {pos: [2, 5, 1], state: "actualgenerators:machine_casing{formed:true}"},
        {pos: [2, 5, 2], state: "actualgenerators:machine_casing{formed:true}"},
        {pos: [0, 6, 0], state: "actualgenerators:machine_casing{formed:true}"},
        {pos: [0, 6, 1], state: "actualgenerators:machine_casing{formed:true}"},
        {pos: [0, 6, 2], state: "actualgenerators:machine_casing{formed:true}"},
        {pos: [1, 6, 0], state: "actualgenerators:machine_casing{formed:true}"},
        {pos: [1, 6, 1], state: "actualgenerators:machine_casing{formed:true}"},
        {pos: [1, 6, 2], state: "actualgenerators:machine_casing{formed:true}"},
        {pos: [2, 6, 0], state: "actualgenerators:machine_casing{formed:true}"},
        {pos: [2, 6, 1], state: "actualgenerators:machine_casing{formed:true}"},
        {pos: [2, 6, 2], state: "actualgenerators:machine_casing{formed:true}"}
    ],
    entities: [],
    palette: [
        "actualgenerators:machine_casing{formed:true}",
        "actualgenerators:annihilation_furnace{facing:north,formed:true}",
        "actualgenerators:corium{level:0}",
        "actualgenerators:item_hatch{facing:north,formed:true}",
        "actualgenerators:energy_hatch{facing:north,formed:true}",
        "actualgenerators:redstone_hatch{facing:north,formed:true}"
    ]
}
